<mujoco model='cloth'>
    <compiler inertiafromgeom='auto' angle='radian'/>
    <size nconmax="1000" njmax="5000" nstack="1000000"/>
    <option timestep="0.002" solver="CG" tolerance="1e-6"/>

    <default>
        <joint limited='true' damping='1' armature='0'/>
        <geom contype='1' conaffinity='1' condim='3' rgba='0.8 0.6 .4 1'
        	margin="0.001" solref=".02 1" solimp=".8 .8 .01" material="geom"/>
    </default>

    <visual>
        <map fogstart="3" fogend="5" force="0.1" znear="0.1"/>
        <quality shadowsize="2048"/>
        <global offwidth="800" offheight="800"/>
    </visual>

    <asset>
        <texture type="skybox" builtin="flat" width="128" height="128" rgb1="1 1 1" rgb2="1 1 1"/>  
        <texture name="texgeom" type="cube" builtin="flat" mark="cross" width="127" height="1278" 
            rgb1="0.8 0.6 0.4" rgb2="0.8 0.6 0.4" markrgb="1 1 1" random="0.01"/>  
        <texture name="texplane" type="2d" builtin="checker" rgb1=".2 .3 .4" rgb2=".1 0.15 0.2" 
            width="512" height="512"/>

        <texture name="texcloth" type="2d" builtin="checker" rgb1="1.0 .4 .4" rgb2=".5 .2 .2" 
            width="512" height="512"/>  

        <material name='MatPlane' reflectance='0.5' texture="texplane" texrepeat="1 1" texuniform="true"/>
        <material name='geom' texture="texgeom" texuniform="true"/>
        <material name="cloth" texture="texcloth" texuniform="true"/>
    </asset>

    <worldbody>     
        <light directional='false' diffuse='.8 .8 .8' specular='0.3 0.3 0.3' ambient='0.1 0.1 0.1' pos='0 1 3.0' dir='0 -.15 -1'/>
		{# <geom name='floor' pos='0 0 -{{ table_height }}' size='3 3 .125' type='plane' material="MatPlane" condim='3'/> #}
        <geom name='table_top' pos='0 {{ table_y }} -0.04' size='{{ table_size/2 }} {{ table_size/2 }} 0.04' type='box' material='geom'/>
        <geom name='table_leg' pos='0 {{ table_y }} -{{ table_height/2+0.08 }}' size='0.05 0.05 {{ table_height/2 }}' type='box' material='geom'/>

        <body name="B0_0" pos="-{{ cloth_spacing*12/2 }} 0 0" euler="-1.57 0 0">
            <freejoint/>
            <composite type="cloth" count="13 13 1" spacing="{{ cloth_spacing }}" flatinertia="0.01">
            <joint kind="main" damping="0.001"/>
            <joint kind="twist" damping="0.0001"/>
            <geom type="capsule" size="{{ cloth_spacing*0.3 }} {{ cloth_spacing*0.2 }}" rgba=".8 .2 .1 1" 
                friction="0.1 0.005 0.0001" mass="{{ cloth_density*((cloth_spacing*12)**2)/(13**2)}}"/>
            <skin material="cloth" texcoord="true" inflate="0.005" subgrid="2"/>
            </composite>
        </body>

        <body name="gripper" pos="0 0 0">
			<geom conaffinity="2" contype="2" pos="-{{ cloth_spacing*6 }} -0.02 0.02" rgba="1.0 1.0 1.0 0.5" size="0.015 0.03" type="capsule" mass="0.05"></geom>
            <geom conaffinity="2" contype="2" pos="-{{ cloth_spacing*6 }} 0.02 0.02" rgba="1.0 1.0 1.0 0.5" size="0.015 0.03" type="capsule" mass="0.05"></geom>
            <geom conaffinity="2" contype="2" pos="-{{ cloth_spacing*6 }} 0 0.07" rgba="1.0 1.0 1.0 0.5" size="0.015 0.04 0.02" type="box" mass="10"></geom>
            <geom conaffinity="2" contype="2" pos="{{ cloth_spacing*6 }} -0.02 0.02" rgba="1.0 1.0 1.0 0.5" size="0.015 0.03" type="capsule" mass="0.05"></geom>
            <geom conaffinity="2" contype="2" pos="{{ cloth_spacing*6 }} 0.02 0.02" rgba="1.0 1.0 1.0 0.5" size="0.015 0.03" type="capsule" mass="0.05"></geom>
            <geom conaffinity="2" contype="2" pos="{{ cloth_spacing*6 }} 0 0.07" rgba="1.0 1.0 1.0 0.5" size="0.015 0.04 0.02" type="box" mass="10"></geom>

            <joint name="gy" type="slide" axis="0 1 0" limited="false" damping='0' armature="1000"/>
            <joint name="gz" type="slide" axis="0 0 1" limited="false" damping='0' armature="1000"/>
		</body>
    </worldbody>

    <equality>
        <connect body1="gripper" body2="B0_0" anchor="-{{ cloth_spacing*6 }} 0 0"/>
        <connect body1="gripper" body2="B12_0" anchor="{{ cloth_spacing*6 }} 0 0"/>
    </equality>

    <actuator>
        <motor name="y_motor" joint="gy" ctrllimited="false"/>
        <motor name="z_motor" joint="gz" ctrllimited="false"/>
    </actuator>
</mujoco>
